Workbook
Name MonthList: History!$AZ$2:$AZ$25

Sheet Dashboard
A1: Monthly Budget Dashboard | E1: Viewing month: | F1: May 2026
A2: ="Showing: "&F1 -> Showing: May 2026
A4: This month | C4: Budget | D4: Actual | E4: Variance | G4: Category | H4: Budget | I4: Actual
A5: Total Income | C5: =SUMIFS(INDEX(History!$C$4:$AY$39,0,MATCH($F$1,History!$C$2:$AY$2,0)),History!$B$4:$B$39,"Income") -> 8550 | D5: =SUMIFS(INDEX(History!$C$4:$AY$39,0,MATCH($F$1,History!$C$2:$AY$2,0)+1),History!$B$4:$B$39,"Income") -> 8550 | E5: =D5-C5 -> 0 | G5: Fixed | H5: =C6 -> 5520.13 | I5: =D6 -> 5520.13
A6: Fixed Expenses | C6: =SUMIFS(INDEX(History!$C$4:$AY$39,0,MATCH($F$1,History!$C$2:$AY$2,0)),History!$B$4:$B$39,"Fixed") -> 5520.13 | D6: =SUMIFS(INDEX(History!$C$4:$AY$39,0,MATCH($F$1,History!$C$2:$AY$2,0)+1),History!$B$4:$B$39,"Fixed") -> 5520.13 | E6: =C6-D6 -> 0 | G6: Variable | H6: =C7 -> 1470 | I6: =D7 -> 1470
A7: Variable Expenses | C7: =SUMIFS(INDEX(History!$C$4:$AY$39,0,MATCH($F$1,History!$C$2:$AY$2,0)),History!$B$4:$B$39,"Variable") -> 1470 | D7: =SUMIFS(INDEX(History!$C$4:$AY$39,0,MATCH($F$1,History!$C$2:$AY$2,0)+1),History!$B$4:$B$39,"Variable") -> 1470 | E7: =C7-D7 -> 0 | G7: Pets | H7: =C8 -> 260.8 | I7: =D8 -> 260.8
A8: Pets | C8: =SUMIFS(INDEX(History!$C$4:$AY$39,0,MATCH($F$1,History!$C$2:$AY$2,0)),History!$B$4:$B$39,"Pets") -> 260.8 | D8: =SUMIFS(INDEX(History!$C$4:$AY$39,0,MATCH($F$1,History!$C$2:$AY$2,0)+1),History!$B$4:$B$39,"Pets") -> 260.8 | E8: =C8-D8 -> 0 | G8: Savings | H8: =C9 -> 1200 | I8: =D9 -> 1200
A9: Savings & Goals | C9: =SUMIFS(INDEX(History!$C$4:$AY$39,0,MATCH($F$1,History!$C$2:$AY$2,0)),History!$B$4:$B$39,"Savings") -> 1200 | D9: =SUMIFS(INDEX(History!$C$4:$AY$39,0,MATCH($F$1,History!$C$2:$AY$2,0)+1),History!$B$4:$B$39,"Savings") -> 1200 | E9: =C9-D9 -> 0
A10: Total Outgoings | C10: =C6+C7+C8+C9 -> 8450.93 | D10: =D6+D7+D8+D9 -> 8450.93 | E10: =C10-D10 -> 0
A11: Left to Allocate | C11: =C5-C10 -> 99.07 | D11: =D5-D10 -> 99.07
A13: Key Ratios
A14: Savings rate | C14: =IF(D5=0,0,D9/D5) -> 0.14035088
A15: Fixed cost ratio | C15: =IF(D5=0,0,D6/D5) -> 0.64562924
A16: Disposable % of income | C16: =IF(D5=0,0,D11/D5) -> 0.011587135
A17: Budget variance (under/(over)) | C17: =C10-D10 -> 0
A19: How to use
A20: 1. Pick any month from the dropdown in F1 to view its data.
A21: 2. Current month (May 2026) on the Budget sheet: edit blue cells for budget, type Actuals in column D.
A22: 3. On Budget, use the "Compare to" dropdown in H1 to see any past month alongside current.
A23: 4. The History tab stores every month as a column pair (Budget | Actual). Nov 2025 is seeded.
A24: 5. To archive a new month: on History, select the live May 2026 pair (E4:F39), copy, right-click → Paste Values. Rename header and add a fresh month pair to the right.

Sheet Budget
A1: Monthly Budget | E1: Reporting month: | F1: May 2026 | G1: Compare to: | H1: Nov 2025
A3: Category | B3: Group | C3: Budget | D3: Actual | E3: Variance | F3: % Used | G3: Hist Budget | H3: Hist Actual | I3: Δ vs current
A4: INCOME
A5: Salary 1 | B5: Income | C5: 4200 | D5: =C5 -> 4200 | E5: =D5-C5 -> 0 | F5: =IF(C5=0,0,D5/C5) -> 1 | G5: =IFERROR(INDEX(History!$C$4:$AY$39, MATCH($A5,History!$A$4:$A$39,0), MATCH($H$1,History!$C$2:$AY$2,0)), "") -> 4200 | H5: {=IFERROR(INDEX(History!$C$4:$AY$39, MATCH($A5,History!$A$4:$A$39,0), MATCH($H$1,History!$C$2:$AY$2,0)+1), "")} -> 4200 | I5: =IFERROR(D5-H5, "") -> 0
A6: Salary 2 | B6: Income | C6: 4350 | D6: =C6 -> 4350 | E6: =D6-C6 -> 0 | F6: =IF(C6=0,0,D6/C6) -> 1 | G6: =IFERROR(INDEX(History!$C$4:$AY$39, MATCH($A6,History!$A$4:$A$39,0), MATCH($H$1,History!$C$2:$AY$2,0)), "") -> 4350 | H6: {=IFERROR(INDEX(History!$C$4:$AY$39, MATCH($A6,History!$A$4:$A$39,0), MATCH($H$1,History!$C$2:$AY$2,0)+1), "")} -> 4350 | I6: =IFERROR(D6-H6, "") -> 0
A7: Other Income | B7: Income | C7: 0 | D7: =C7 -> 0 | E7: =D7-C7 -> 0 | F7: =IF(C7=0,0,D7/C7) -> 0 | G7: =IFERROR(INDEX(History!$C$4:$AY$39, MATCH($A7,History!$A$4:$A$39,0), MATCH($H$1,History!$C$2:$AY$2,0)), "") -> 0 | H7: {=IFERROR(INDEX(History!$C$4:$AY$39, MATCH($A7,History!$A$4:$A$39,0), MATCH($H$1,History!$C$2:$AY$2,0)+1), "")} -> 0 | I7: =IFERROR(D7-H7, "") -> 0
A8: Total Income | C8: =SUMIF(B5:B7,"Income",C5:C7) -> 8550 | D8: =SUMIF(B5:B7,"Income",D5:D7) -> 8550 | E8: =D8-C8 -> 0
A10: FIXED EXPENSES
A11: Mortgage | B11: Fixed | C11: 2200 | D11: =C11 -> 2200 | E11: =C11-D11 -> 0 | F11: =IF(C11=0,0,D11/C11) -> 1 | G11: =IFERROR(INDEX(History!$C$4:$AY$39, MATCH($A11,History!$A$4:$A$39,0), MATCH($H$1,History!$C$2:$AY$2,0)), "") -> 2200 | H11: {=IFERROR(INDEX(History!$C$4:$AY$39, MATCH($A11,History!$A$4:$A$39,0), MATCH($H$1,History!$C$2:$AY$2,0)+1), "")} -> 2200 | I11: =IFERROR(D11-H11, "") -> 0
A12: Energy | B12: Fixed | C12: 162 | D12: =C12 -> 162 | E12: =C12-D12 -> 0 | F12: =IF(C12=0,0,D12/C12) -> 1 | G12: =IFERROR(INDEX(History!$C$4:$AY$39, MATCH($A12,History!$A$4:$A$39,0), MATCH($H$1,History!$C$2:$AY$2,0)), "") -> 162 | H12: {=IFERROR(INDEX(History!$C$4:$AY$39, MATCH($A12,History!$A$4:$A$39,0), MATCH($H$1,History!$C$2:$AY$2,0)+1), "")} -> 162 | I12: =IFERROR(D12-H12, "") -> 0
A13: Nursery | B13: Fixed | C13: 1122 | D13: =C13 -> 1122 | E13: =C13-D13 -> 0 | F13: =IF(C13=0,0,D13/C13) -> 1 | G13: =IFERROR(INDEX(History!$C$4:$AY$39, MATCH($A13,History!$A$4:$A$39,0), MATCH($H$1,History!$C$2:$AY$2,0)), "") -> 1122 | H13: {=IFERROR(INDEX(History!$C$4:$AY$39, MATCH($A13,History!$A$4:$A$39,0), MATCH($H$1,History!$C$2:$AY$2,0)+1), "")} -> 1122 | I13: =IFERROR(D13-H13, "") -> 0
A14: Vet Success | B14: Fixed | C14: 16.5 | D14: =C14 -> 16.5 | E14: =C14-D14 -> 0 | F14: =IF(C14=0,0,D14/C14) -> 1 | G14: =IFERROR(INDEX(History!$C$4:$AY$39, MATCH($A14,History!$A$4:$A$39,0), MATCH($H$1,History!$C$2:$AY$2,0)), "") -> 16.5 | H14: {=IFERROR(INDEX(History!$C$4:$AY$39, MATCH($A14,History!$A$4:$A$39,0), MATCH($H$1,History!$C$2:$AY$2,0)+1), "")} -> 16.5 | I14: =IFERROR(D14-H14, "") -> 0
A15: EE | B15: Fixed | C15: 91 | D15: =C15 -> 91 | E15: =C15-D15 -> 0 | F15: =IF(C15=0,0,D15/C15) -> 1 | G15: =IFERROR(INDEX(History!$C$4:$AY$39, MATCH($A15,History!$A$4:$A$39,0), MATCH($H$1,History!$C$2:$AY$2,0)), "") -> 91 | H15: {=IFERROR(INDEX(History!$C$4:$AY$39, MATCH($A15,History!$A$4:$A$39,0), MATCH($H$1,History!$C$2:$AY$2,0)+1), "")} -> 91 | I15: =IFERROR(D15-H15, "") -> 0
A16: TV License | B16: Fixed | C16: 15 | D16: =C16 -> 15 | E16: =C16-D16 -> 0 | F16: =IF(C16=0,0,D16/C16) -> 1 | G16: =IFERROR(INDEX(History!$C$4:$AY$39, MATCH($A16,History!$A$4:$A$39,0), MATCH($H$1,History!$C$2:$AY$2,0)), "") -> 15 | H16: {=IFERROR(INDEX(History!$C$4:$AY$39, MATCH($A16,History!$A$4:$A$39,0), MATCH($H$1,History!$C$2:$AY$2,0)+1), "")} -> 15 | I16: =IFERROR(D16-H16, "") -> 0
A17: Alz donation | B17: Fixed | C17: 0 | D17: =C17 -> 0 | E17: =C17-D17 -> 0 | F17: =IF(C17=0,0,D17/C17) -> 0 | G17: =IFERROR(INDEX(History!$C$4:$AY$39, MATCH($A17,History!$A$4:$A$39,0), MATCH($H$1,History!$C$2:$AY$2,0)), "") -> 0 | H17: {=IFERROR(INDEX(History!$C$4:$AY$39, MATCH($A17,History!$A$4:$A$39,0), MATCH($H$1,History!$C$2:$AY$2,0)+1), "")} -> 0 | I17: =IFERROR(D17-H17, "") -> 0
A18: Home insurance | B18: Fixed | C18: 72.74 | D18: =C18 -> 72.74 | E18: =C18-D18 -> 0 | F18: =IF(C18=0,0,D18/C18) -> 1 | G18: =IFERROR(INDEX(History!$C$4:$AY$39, MATCH($A18,History!$A$4:$A$39,0), MATCH($H$1,History!$C$2:$AY$2,0)), "") -> 72.74 | H18: {=IFERROR(INDEX(History!$C$4:$AY$39, MATCH($A18,History!$A$4:$A$39,0), MATCH($H$1,History!$C$2:$AY$2,0)+1), "")} -> 72.74 | I18: =IFERROR(D18-H18, "") -> 0
A19: Happy tiddlers | B19: Fixed | C19: 53.72 | D19: =C19 -> 53.72 | E19: =C19-D19 -> 0 | F19: =IF(C19=0,0,D19/C19) -> 1 | G19: =IFERROR(INDEX(History!$C$4:$AY$39, MATCH($A19,History!$A$4:$A$39,0), MATCH($H$1,History!$C$2:$AY$2,0)), "") -> 53.72 | H19: {=IFERROR(INDEX(History!$C$4:$AY$39, MATCH($A19,History!$A$4:$A$39,0), MATCH($H$1,History!$C$2:$AY$2,0)+1), "")} -> 53.72 | I19: =IFERROR(D19-H19, "") -> 0
A20: Car parking | B20: Fixed | C20: 90 | D20: =C20 -> 90 | E20: =C20-D20 -> 0 | F20: =IF(C20=0,0,D20/C20) -> 1 | G20: =IFERROR(INDEX(History!$C$4:$AY$39, MATCH($A20,History!$A$4:$A$39,0), MATCH($H$1,History!$C$2:$AY$2,0)), "") -> 90 | H20: {=IFERROR(INDEX(History!$C$4:$AY$39, MATCH($A20,History!$A$4:$A$39,0), MATCH($H$1,History!$C$2:$AY$2,0)+1), "")} -> 90 | I20: =IFERROR(D20-H20, "") -> 0
A21: Council Tax | B21: Fixed | C21: 334 | D21: =C21 -> 334 | E21: =C21-D21 -> 0 | F21: =IF(C21=0,0,D21/C21) -> 1 | G21: =IFERROR(INDEX(History!$C$4:$AY$39, MATCH($A21,History!$A$4:$A$39,0), MATCH($H$1,History!$C$2:$AY$2,0)), "") -> 334 | H21: {=IFERROR(INDEX(History!$C$4:$AY$39, MATCH($A21,History!$A$4:$A$39,0), MATCH($H$1,History!$C$2:$AY$2,0)+1), "")} -> 334 | I21: =IFERROR(D21-H21, "") -> 0
A22: Water | B22: Fixed | C22: 66 | D22: =C22 -> 66 | E22: =C22-D22 -> 0 | F22: =IF(C22=0,0,D22/C22) -> 1 | G22: =IFERROR(INDEX(History!$C$4:$AY$39, MATCH($A22,History!$A$4:$A$39,0), MATCH($H$1,History!$C$2:$AY$2,0)), "") -> 66 | H22: {=IFERROR(INDEX(History!$C$4:$AY$39, MATCH($A22,History!$A$4:$A$39,0), MATCH($H$1,History!$C$2:$AY$2,0)+1), "")} -> 66 | I22: =IFERROR(D22-H22, "") -> 0
... A32: Kitchen | B32: Fixed | C32: 426.42 | D32: =C32 -> 426.42 | E32: =C32-D32 -> 0 | F32: =IF(C32=0,0,D32/C32) -> 1 | G32: =IFERROR(INDEX(History!$C$4:$AY$39, MATCH($A32,History!$A$4:$A$39,0), MATCH($H$1,History!$C$2:$AY$2,0)), "") -> 426.42 | H32: {=IFERROR(INDEX(History!$C$4:$AY$39, MATCH($A32,History!$A$4:$A$39,0), MATCH($H$1,History!$C$2:$AY$2,0)+1), "")} -> 426.42 | I32: =IFERROR(D32-H32, "") -> 0
A33: Total Fixed | C33: =SUMIF($B$11:$B$32,"Fixed",C11:C32) -> 5520.13 | D33: =SUMIF($B$11:$B$32,"Fixed",D11:D32) -> 5520.13 | E33: =C33-D33 -> 0 | F33: =IF(C33=0,0,D33/C33) -> 1
A34: VARIABLE EXPENSES
A35: Food | B35: Variable | C35: 600 | D35: =C35 -> 600 | E35: =C35-D35 -> 0 | F35: =IF(C35=0,0,D35/C35) -> 1 | G35: =IFERROR(INDEX(History!$C$4:$AY$39, MATCH($A35,History!$A$4:$A$39,0), MATCH($H$1,History!$C$2:$AY$2,0)), "") -> 600 | H35: {=IFERROR(INDEX(History!$C$4:$AY$39, MATCH($A35,History!$A$4:$A$39,0), MATCH($H$1,History!$C$2:$AY$2,0)+1), "")} -> 600 | I35: =IFERROR(D35-H35, "") -> 0
A36: Petrol | B36: Variable | C36: 100 | D36: =C36 -> 100 | E36: =C36-D36 -> 0 | F36: =IF(C36=0,0,D36/C36) -> 1 | G36: =IFERROR(INDEX(History!$C$4:$AY$39, MATCH($A36,History!$A$4:$A$39,0), MATCH($H$1,History!$C$2:$AY$2,0)), "") -> 100 | H36: {=IFERROR(INDEX(History!$C$4:$AY$39, MATCH($A36,History!$A$4:$A$39,0), MATCH($H$1,History!$C$2:$AY$2,0)+1), "")} -> 100 | I36: =IFERROR(D36-H36, "") -> 0
A37: Cleaner | B37: Variable | C37: 70 | D37: =C37 -> 70 | E37: =C37-D37 -> 0 | F37: =IF(C37=0,0,D37/C37) -> 1 | G37: =IFERROR(INDEX(History!$C$4:$AY$39, MATCH($A37,History!$A$4:$A$39,0), MATCH($H$1,History!$C$2:$AY$2,0)), "") -> 70 | H37: {=IFERROR(INDEX(History!$C$4:$AY$39, MATCH($A37,History!$A$4:$A$39,0), MATCH($H$1,History!$C$2:$AY$2,0)+1), "")} -> 70 | I37: =IFERROR(D37-H37, "") -> 0
A38: Travel | B38: Variable | C38: 600 | D38: =C38 -> 600 | E38: =C38-D38 -> 0 | F38: =IF(C38=0,0,D38/C38) -> 1 | G38: =IFERROR(INDEX(History!$C$4:$AY$39, MATCH($A38,History!$A$4:$A$39,0), MATCH($H$1,History!$C$2:$AY$2,0)), "") -> 600 | H38: {=IFERROR(INDEX(History!$C$4:$AY$39, MATCH($A38,History!$A$4:$A$39,0), MATCH($H$1,History!$C$2:$AY$2,0)+1), "")} -> 600 | I38: =IFERROR(D38-H38, "") -> 0
A39: Doggy day care | B39: Variable | C39: 100 | D39: =C39 -> 100 | E39: =C39-D39 -> 0 | F39: =IF(C39=0,0,D39/C39) -> 1 | G39: =IFERROR(INDEX(History!$C$4:$AY$39, MATCH($A39,History!$A$4:$A$39,0), MATCH($H$1,History!$C$2:$AY$2,0)), "") -> 100 | H39: {=IFERROR(INDEX(History!$C$4:$AY$39, MATCH($A39,History!$A$4:$A$39,0), MATCH($H$1,History!$C$2:$AY$2,0)+1), "")} -> 100 | I39: =IFERROR(D39-H39, "") -> 0
A40: Total Variable | C40: =SUMIF($B$35:$B$39,"Variable",C35:C39) -> 1470 | D40: =SUMIF($B$35:$B$39,"Variable",D35:D39) -> 1470 | E40: =C40-D40 -> 0 | F40: =IF(C40=0,0,D40/C40) -> 1
A41: PETS
A42: Leia Food | B42: Pets | C42: 100 | D42: =C42 -> 100 | E42: =C42-D42 -> 0 | F42: =IF(C42=0,0,D42/C42) -> 1 | G42: =IFERROR(INDEX(History!$C$4:$AY$39, MATCH($A42,History!$A$4:$A$39,0), MATCH($H$1,History!$C$2:$AY$2,0)), "") -> 100 | H42: {=IFERROR(INDEX(History!$C$4:$AY$39, MATCH($A42,History!$A$4:$A$39,0), MATCH($H$1,History!$C$2:$AY$2,0)+1), "")} -> 100 | I42: =IFERROR(D42-H42, "") -> 0
A43: Charlie Hair | B43: Pets | C43: 128.3 | D43: =C43 -> 128.3 | E43: =C43-D43 -> 0 | F43: =IF(C43=0,0,D43/C43) -> 1 | G43: =IFERROR(INDEX(History!$C$4:$AY$39, MATCH($A43,History!$A$4:$A$39,0), MATCH($H$1,History!$C$2:$AY$2,0)), "") -> 128.3 | H43: {=IFERROR(INDEX(History!$C$4:$AY$39, MATCH($A43,History!$A$4:$A$39,0), MATCH($H$1,History!$C$2:$AY$2,0)+1), "")} -> 128.3 | I43: =IFERROR(D43-H43, "") -> 0
A44: Leia Groom | B44: Pets | C44: 32.5 | D44: =C44 -> 32.5 | E44: =C44-D44 -> 0 | F44: =IF(C44=0,0,D44/C44) -> 1 | G44: =IFERROR(INDEX(History!$C$4:$AY$39, MATCH($A44,History!$A$4:$A$39,0), MATCH($H$1,History!$C$2:$AY$2,0)), "") -> 32.5 | H44: {=IFERROR(INDEX(History!$C$4:$AY$39, MATCH($A44,History!$A$4:$A$39,0), MATCH($H$1,History!$C$2:$AY$2,0)+1), "")} -> 32.5 | I44: =IFERROR(D44-H44, "") -> 0
A45: Total Pets | C45: =SUMIF($B$42:$B$44,"Pets",C42:C44) -> 260.8 | D45: =SUMIF($B$42:$B$44,"Pets",D42:D44) -> 260.8 | E45: =C45-D45 -> 0 | F45: =IF(C45=0,0,D45/C45) -> 1
A46: SAVINGS & GOALS
A47: Savings transfer | B47: Savings | C47: 800 | D47: =C47 -> 800 | E47: =C47-D47 -> 0 | F47: =IF(C47=0,0,D47/C47) -> 1 | G47: =IFERROR(INDEX(History!$C$4:$AY$39, MATCH($A47,History!$A$4:$A$39,0), MATCH($H$1,History!$C$2:$AY$2,0)), "") -> 800 | H47: {=IFERROR(INDEX(History!$C$4:$AY$39, MATCH($A47,History!$A$4:$A$39,0), MATCH($H$1,History!$C$2:$AY$2,0)+1), "")} -> 800 | I47: =IFERROR(D47-H47, "") -> 0
A48: Goals funding | B48: Savings | C48: 400 | D48: =C48 -> 400 | E48: =C48-D48 -> 0 | F48: =IF(C48=0,0,D48/C48) -> 1 | G48: =IFERROR(INDEX(History!$C$4:$AY$39, MATCH($A48,History!$A$4:$A$39,0), MATCH($H$1,History!$C$2:$AY$2,0)), "") -> 400 | H48: {=IFERROR(INDEX(History!$C$4:$AY$39, MATCH($A48,History!$A$4:$A$39,0), MATCH($H$1,History!$C$2:$AY$2,0)+1), "")} -> 400 | I48: =IFERROR(D48-H48, "") -> 0
A49: Investments | B49: Savings | C49: 0 | D49: =C49 -> 0 | E49: =C49-D49 -> 0 | F49: =IF(C49=0,0,D49/C49) -> 0 | G49: =IFERROR(INDEX(History!$C$4:$AY$39, MATCH($A49,History!$A$4:$A$39,0), MATCH($H$1,History!$C$2:$AY$2,0)), "") -> 0 | H49: {=IFERROR(INDEX(History!$C$4:$AY$39, MATCH($A49,History!$A$4:$A$39,0), MATCH($H$1,History!$C$2:$AY$2,0)+1), "")} -> 0 | I49: =IFERROR(D49-H49, "") -> 0
A50: Total Savings | C50: =SUMIF($B$47:$B$49,"Savings",C47:C49) -> 1200 | D50: =SUMIF($B$47:$B$49,"Savings",D47:D49) -> 1200 | E50: =C50-D50 -> 0 | F50: =IF(C50=0,0,D50/C50) -> 1
A52: TOTAL OUTGOINGS | C52: =C33+C40+C45+C50 -> 8450.93 | D52: =D33+D40+D45+D50 -> 8450.93 | E52: =C52-D52 -> 0 | F52: =IF(C52=0,0,D52/C52) -> 1
...

Sheet Goals
A1: Savings Goals
A3: Goal | B3: Target (£) | C3: Saved (£) | D3: Remaining | E3: % Funded
D4: =IF(B4="","",B4-C4) | E4: =IF(OR(B4="",B4=0),"",C4/B4)
D5: =IF(B5="","",B5-C5) | E5: =IF(OR(B5="",B5=0),"",C5/B5)
D6: =IF(B6="","",B6-C6) | E6: =IF(OR(B6="",B6=0),"",C6/B6)
D7: =IF(B7="","",B7-C7) | E7: =IF(OR(B7="",B7=0),"",C7/B7)
A8: Total | B8: =SUM(B4:B7) -> 0 | C8: =SUM(C4:C7) -> 0 | D8: =B8-C8 -> 0 | E8: =IF(B8=0,0,C8/B8) -> 0
A10: Monthly allocation (from Budget) | B10: =Budget!D48 -> 400
A11: Remaining to fund (all goals) | B11: =D8 -> 0
A12: Months to fully fund at current pace | B12: =IF(OR(B10=0,B11=0),"—",ROUNDUP(B11/B10,0)) -> —

Sheet Investments
A1: Investments & Savings Pot
A3: Monthly allocations (from Budget)
A4: Savings transfer | B4: =Budget!D47 -> 800
A5: Goals funding | B5: =Budget!D48 -> 400
A6: Investments contribution | B6: =Budget!D49 -> 0
A7: Total monthly savings | B7: =SUM(B4:B6) -> 1200
A9: Account balances | B9: Balance (£)
A14: Total pot | B14: =SUM(B10:B13) -> 0
A15: Less: committed to goals | B15: =Goals!B8 -> 0
A16: Uncommitted buffer | B16: =B14-B15 -> 0
A18: Projection
A19: Pot + 12 months at current pace | B19: =B14+B7*12 -> 14400
A20: Pot + 6 months at current pace | B20: =B14+B7*6 -> 7200

Sheet History
A1: Historical Monthly Archive | C1: View month: | D1: Nov 2025 | H1: Live / Saved | AZ1: Month List (helper)
A2: Each month pair (Budget | Actual) is a snapshot. Use the 'Save to history' workflow on the Budget sheet to add a new month. | C2: Nov 2025 | E2: May 2026 | H2: Purple italic = live formulas pulling from Budget sheet. To lock a month in: select the month pair, copy, paste-special as values. | AZ2: {=IFERROR(IF(INDEX($2:$2, 3+(ROW()-2)*2)=0,"",INDEX($2:$2, 3+(ROW()-2)*2)&""), "")} -> Nov 2025
A3: Category | B3: Group | C3: Budget | D3: Actual | E3: Budget | F3: Actual | AZ3: {=IFERROR(IF(INDEX($2:$2, 3+(ROW()-2)*2)=0,"",INDEX($2:$2, 3+(ROW()-2)*2)&""), "")} -> May 2026
A4: Salary 1 | B4: Income | C4: 4200 | D4: 4200 | E4: =IFERROR(VLOOKUP($A4,Budget!$A$5:$D$49,3,FALSE),0) -> 4200 | F4: =IFERROR(VLOOKUP($A4,Budget!$A$5:$D$49,4,FALSE),0) -> 4200 | AZ4: {=IFERROR(IF(INDEX($2:$2, 3+(ROW()-2)*2)=0,"",INDEX($2:$2, 3+(ROW()-2)*2)&""), "")}
A5: Salary 2 | B5: Income | C5: 4350 | D5: 4350 | E5: =IFERROR(VLOOKUP($A5,Budget!$A$5:$D$49,3,FALSE),0) -> 4350 | F5: =IFERROR(VLOOKUP($A5,Budget!$A$5:$D$49,4,FALSE),0) -> 4350 | AZ5: {=IFERROR(IF(INDEX($2:$2, 3+(ROW()-2)*2)=0,"",INDEX($2:$2, 3+(ROW()-2)*2)&""), "")}
A6: Other Income | B6: Income | C6: 0 | D6: 0 | E6: =IFERROR(VLOOKUP($A6,Budget!$A$5:$D$49,3,FALSE),0) -> 0 | F6: =IFERROR(VLOOKUP($A6,Budget!$A$5:$D$49,4,FALSE),0) -> 0 | AZ6: {=IFERROR(IF(INDEX($2:$2, 3+(ROW()-2)*2)=0,"",INDEX($2:$2, 3+(ROW()-2)*2)&""), "")}
A7: Mortgage | B7: Fixed | C7: 2200 | D7: 2200 | E7: =IFERROR(VLOOKUP($A7,Budget!$A$5:$D$49,3,FALSE),0) -> 2200 | F7: =IFERROR(VLOOKUP($A7,Budget!$A$5:$D$49,4,FALSE),0) -> 2200 | AZ7: {=IFERROR(IF(INDEX($2:$2, 3+(ROW()-2)*2)=0,"",INDEX($2:$2, 3+(ROW()-2)*2)&""), "")}
A8: Energy | B8: Fixed | C8: 162 | D8: 162 | E8: =IFERROR(VLOOKUP($A8,Budget!$A$5:$D$49,3,FALSE),0) -> 162 | F8: =IFERROR(VLOOKUP($A8,Budget!$A$5:$D$49,4,FALSE),0) -> 162 | AZ8: {=IFERROR(IF(INDEX($2:$2, 3+(ROW()-2)*2)=0,"",INDEX($2:$2, 3+(ROW()-2)*2)&""), "")}
A9: Nursery | B9: Fixed | C9: 1122 | D9: 1122 | E9: =IFERROR(VLOOKUP($A9,Budget!$A$5:$D$49,3,FALSE),0) -> 1122 | F9: =IFERROR(VLOOKUP($A9,Budget!$A$5:$D$49,4,FALSE),0) -> 1122 | AZ9: {=IFERROR(IF(INDEX($2:$2, 3+(ROW()-2)*2)=0,"",INDEX($2:$2, 3+(ROW()-2)*2)&""), "")}
A10: Vet Success | B10: Fixed | C10: 16.5 | D10: 16.5 | E10: =IFERROR(VLOOKUP($A10,Budget!$A$5:$D$49,3,FALSE),0) -> 16.5 | F10: =IFERROR(VLOOKUP($A10,Budget!$A$5:$D$49,4,FALSE),0) -> 16.5 | AZ10: {=IFERROR(IF(INDEX($2:$2, 3+(ROW()-2)*2)=0,"",INDEX($2:$2, 3+(ROW()-2)*2)&""), "")}
A11: EE | B11: Fixed | C11: 91 | D11: 91 | E11: =IFERROR(VLOOKUP($A11,Budget!$A$5:$D$49,3,FALSE),0) -> 91 | F11: =IFERROR(VLOOKUP($A11,Budget!$A$5:$D$49,4,FALSE),0) -> 91 | AZ11: {=IFERROR(IF(INDEX($2:$2, 3+(ROW()-2)*2)=0,"",INDEX($2:$2, 3+(ROW()-2)*2)&""), "")}
A12: TV License | B12: Fixed | C12: 15 | D12: 15 | E12: =IFERROR(VLOOKUP($A12,Budget!$A$5:$D$49,3,FALSE),0) -> 15 | F12: =IFERROR(VLOOKUP($A12,Budget!$A$5:$D$49,4,FALSE),0) -> 15 | AZ12: {=IFERROR(IF(INDEX($2:$2, 3+(ROW()-2)*2)=0,"",INDEX($2:$2, 3+(ROW()-2)*2)&""), "")}
A13: Alz donation | B13: Fixed | C13: 0 | D13: 0 | E13: =IFERROR(VLOOKUP($A13,Budget!$A$5:$D$49,3,FALSE),0) -> 0 | F13: =IFERROR(VLOOKUP($A13,Budget!$A$5:$D$49,4,FALSE),0) -> 0 | AZ13: {=IFERROR(IF(INDEX($2:$2, 3+(ROW()-2)*2)=0,"",INDEX($2:$2, 3+(ROW()-2)*2)&""), "")}
A14: Home insurance | B14: Fixed | C14: 72.74 | D14: 72.74 | E14: =IFERROR(VLOOKUP($A14,Budget!$A$5:$D$49,3,FALSE),0) -> 72.74 | F14: =IFERROR(VLOOKUP($A14,Budget!$A$5:$D$49,4,FALSE),0) -> 72.74 | AZ14: {=IFERROR(IF(INDEX($2:$2, 3+(ROW()-2)*2)=0,"",INDEX($2:$2, 3+(ROW()-2)*2)&""), "")}
A15: Happy tiddlers | B15: Fixed | C15: 53.72 | D15: 53.72 | E15: =IFERROR(VLOOKUP($A15,Budget!$A$5:$D$49,3,FALSE),0) -> 53.72 | F15: =IFERROR(VLOOKUP($A15,Budget!$A$5:$D$49,4,FALSE),0) -> 53.72 | AZ15: {=IFERROR(IF(INDEX($2:$2, 3+(ROW()-2)*2)=0,"",INDEX($2:$2, 3+(ROW()-2)*2)&""), "")}
... A25: Sport | B25: Fixed | C25: 55 | D25: 55 | E25: =IFERROR(VLOOKUP($A25,Budget!$A$5:$D$49,3,FALSE),0) -> 55 | F25: =IFERROR(VLOOKUP($A25,Budget!$A$5:$D$49,4,FALSE),0) -> 55 | AZ25: {=IFERROR(IF(INDEX($2:$2, 3+(ROW()-2)*2)=0,"",INDEX($2:$2, 3+(ROW()-2)*2)&""), "")}
A26: Tech Pack | B26: Fixed | C26: 15 | D26: 15 | E26: =IFERROR(VLOOKUP($A26,Budget!$A$5:$D$49,3,FALSE),0) -> 15 | F26: =IFERROR(VLOOKUP($A26,Budget!$A$5:$D$49,4,FALSE),0) -> 15
A27: Spotify | B27: Fixed | C27: 20 | D27: 20 | E27: =IFERROR(VLOOKUP($A27,Budget!$A$5:$D$49,3,FALSE),0) -> 20 | F27: =IFERROR(VLOOKUP($A27,Budget!$A$5:$D$49,4,FALSE),0) -> 20
A28: Kitchen | B28: Fixed | C28: 426.42 | D28: 426.42 | E28: =IFERROR(VLOOKUP($A28,Budget!$A$5:$D$49,3,FALSE),0) -> 426.42 | F28: =IFERROR(VLOOKUP($A28,Budget!$A$5:$D$49,4,FALSE),0) -> 426.42
A29: Food | B29: Variable | C29: 600 | D29: 600 | E29: =IFERROR(VLOOKUP($A29,Budget!$A$5:$D$49,3,FALSE),0) -> 600 | F29: =IFERROR(VLOOKUP($A29,Budget!$A$5:$D$49,4,FALSE),0) -> 600
A30: Petrol | B30: Variable | C30: 100 | D30: 100 | E30: =IFERROR(VLOOKUP($A30,Budget!$A$5:$D$49,3,FALSE),0) -> 100 | F30: =IFERROR(VLOOKUP($A30,Budget!$A$5:$D$49,4,FALSE),0) -> 100
A31: Cleaner | B31: Variable | C31: 70 | D31: 70 | E31: =IFERROR(VLOOKUP($A31,Budget!$A$5:$D$49,3,FALSE),0) -> 70 | F31: =IFERROR(VLOOKUP($A31,Budget!$A$5:$D$49,4,FALSE),0) -> 70
A32: Travel | B32: Variable | C32: 600 | D32: 600 | E32: =IFERROR(VLOOKUP($A32,Budget!$A$5:$D$49,3,FALSE),0) -> 600 | F32: =IFERROR(VLOOKUP($A32,Budget!$A$5:$D$49,4,FALSE),0) -> 600
A33: Doggy day care | B33: Variable | C33: 100 | D33: 100 | E33: =IFERROR(VLOOKUP($A33,Budget!$A$5:$D$49,3,FALSE),0) -> 100 | F33: =IFERROR(VLOOKUP($A33,Budget!$A$5:$D$49,4,FALSE),0) -> 100
A34: Leia Food | B34: Pets | C34: 100 | D34: 100 | E34: =IFERROR(VLOOKUP($A34,Budget!$A$5:$D$49,3,FALSE),0) -> 100 | F34: =IFERROR(VLOOKUP($A34,Budget!$A$5:$D$49,4,FALSE),0) -> 100
A35: Charlie Hair | B35: Pets | C35: 128.3 | D35: 128.3 | E35: =IFERROR(VLOOKUP($A35,Budget!$A$5:$D$49,3,FALSE),0) -> 128.3 | F35: =IFERROR(VLOOKUP($A35,Budget!$A$5:$D$49,4,FALSE),0) -> 128.3
A36: Leia Groom | B36: Pets | C36: 32.5 | D36: 32.5 | E36: =IFERROR(VLOOKUP($A36,Budget!$A$5:$D$49,3,FALSE),0) -> 32.5 | F36: =IFERROR(VLOOKUP($A36,Budget!$A$5:$D$49,4,FALSE),0) -> 32.5
A37: Savings transfer | B37: Savings | C37: 800 | D37: 800 | E37: =IFERROR(VLOOKUP($A37,Budget!$A$5:$D$49,3,FALSE),0) -> 800 | F37: =IFERROR(VLOOKUP($A37,Budget!$A$5:$D$49,4,FALSE),0) -> 800
... A39: Investments | B39: Savings | C39: 0 | D39: 0 | E39: =IFERROR(VLOOKUP($A39,Budget!$A$5:$D$49,3,FALSE),0) -> 0 | F39: =IFERROR(VLOOKUP($A39,Budget!$A$5:$D$49,4,FALSE),0) -> 0

Sheet South Africa
A1: South Africa Trip
A3: Item | B3: Cost (£) | C3: Paid (£) | D3: Unpaid (£)
A4: Activity | B4: 0 | C4: 0 | D4: =B4-C4 -> 0
A5: Flights | B5: 994 | C5: 994 | D5: =B5-C5 -> 0
A6: CT Accommodation | B6: 284 | C6: 0 | D6: =B6-C6 -> 284
A7: CT Car | B7: 200 | C7: 0 | D7: =B7-C7 -> 200
A8: CT to Durban | B8: 120 | C8: 0 | D8: =B8-C8 -> 120
A9: Jz to CT | B9: 120 | C9: 0 | D9: =B9-C9 -> 120
A10: Durban Hire | B10: 250 | C10: 0 | D10: =B10-C10 -> 250
A11: Amakhosi | B11: 1400 | C11: 0 | D11: =B11-C11 -> 1400
A12: Sandals | B12: 600 | C12: 0 | D12: =B12-C12 -> 600
A13: Spending money | B13: 2000 | C13: 0 | D13: =B13-C13 -> 2000
A15: Total | B15: =SUM(B4:B13) -> 5968 | C15: =SUM(C4:C13) -> 994 | D15: =SUM(D4:D13) -> 4974
